Workbook

Sheet Portada
C2: Concepto | E2: Monto
C3: Costo del Proyecto | E3: =Global!C14 -> 10504220 | H3: QR DE APP AGREARLO
C4: Administracion 3% | E4: =E3*0.05 -> 525210.98 | H4: CORREO DRIVE NUBE DE ARCHIVOS (AGREGARLO)
C5: Utilidad 20% | E5: =E3*0.2 -> 2100843.9
C6: Costo Total del Proyecto | E6: =SUM(E3:F5) -> 13130274
C9: Conceptos Generales | E9: Monto
C10: Nomina Global | E10: =Global!P5 -> 9171821.4
C11: Traslado Global | E11: =Global!P6 -> 469722
C12: Capacitacion/Examenes | E12: =Global!P7 -> 118800
C13: Uniformes Global | E13: =Global!P8 -> 230400
C14: Herramientas Global | E14: =Global!P9 -> 158945.5
C15: EPP Global | E15: =Global!P10 -> 60640.58
C16: Cuatrimotos Global | E16: =Global!P11 -> 263890
C19: Valores Agregadors
B20: 1 | C20: Implementacion de APP de registro de recorriedo del guardia a los diversos puntos, escanenado el QR/NFC dejando un registro de timepo
C21: en que se ejecuto el recorrido, las veces que se ejecuto el recorrido y la hora en que dicho acontecimiento se dio.
B23: 2 | C23: Documentacion entregable diariamente por medio, el usuario estara informado en tiempo real de la ejecuccion de las actividades y los acontecimientos
C24: mas importantes y/o destacados de cada turno, entregandose un reporte general a las 09:00 horas del dia.
B26: 3 | C26: Riguroso proceso de selección de personal,requisitos especificos , desde cierta formacion escolar, aplicando examenes psicometricos, detector de mentiras
C27: , y entrevista del Coordinador de Seguridad Gerardo Guzman, quien fue formado en Academia de Coporacion Distingida.
B29: 4 | C29: Documentacion profesional, manuales, procesos, contingencias, estrategias, estructuradas para garantiar el perfecto funcionamiento y sincronia de los
C30: colaboradores (Guardias de Seguridad Patrimonial), los cuales se capacitan constantemente, para garantizar el mejor servicio posible
B32: 5 | C32: Asistencia 24/7 por parte de personal administrativo de Micsa Safety , (GRUPO MICSA) para cualquier intervencion necesaria

Sheet Global
B2: COBRO INICIAL DE PROYECTO (INVERSION EL MAS ALTO)
D3: Mes | E3: Mes | F3: Mes | G3: Mes | H3: Mes | I3: Mes | J3: Mes | K3: Mes | L3: Mes | M3: Mes | N3: Mes | O3: Mes | P3: PROYECTO
C4: CONCEPTO | D4: 1 | E4: 2 | F4: 3 | G4: 4 | H4: 5 | I4: 6 | J4: 7 | K4: 8 | L4: 9 | M4: 10 | N4: 11 | O4: 12 | P4: GLOBALES INDIVIDUALES
B5: 1 | C5: Nomina | D5: ='1-Desglozar Nomina'!$D$56 -> 764318.45 | E5: ='1-Desglozar Nomina'!$D$56 -> 764318.45 | F5: ='1-Desglozar Nomina'!$D$56 -> 764318.45 | G5: ='1-Desglozar Nomina'!$D$56 -> 764318.45 | H5: ='1-Desglozar Nomina'!$D$56 -> 764318.45 | I5: ='1-Desglozar Nomina'!$D$56 -> 764318.45 | J5: ='1-Desglozar Nomina'!$D$56 -> 764318.45 | K5: ='1-Desglozar Nomina'!$D$56 -> 764318.45 | ... O5: ='1-Desglozar Nomina'!$D$56 -> 764318.45 | P5: =SUM(D5:O5) -> 9171821.4
B6: 2 | C6: Traslado | D6: ='2-Traslados'!$E$60 -> 39143.5 | E6: ='2-Traslados'!$E$60 -> 39143.5 | F6: ='2-Traslados'!$E$60 -> 39143.5 | G6: ='2-Traslados'!$E$60 -> 39143.5 | H6: ='2-Traslados'!$E$60 -> 39143.5 | I6: ='2-Traslados'!$E$60 -> 39143.5 | J6: ='2-Traslados'!$E$60 -> 39143.5 | K6: ='2-Traslados'!$E$60 -> 39143.5 | ... O6: ='2-Traslados'!$E$60 -> 39143.5 | P6: =SUM(D6:O6) -> 469722
B7: 3 | C7: DC-3, Examen medico Dopaje | D7: ='3-DC-3 MED-DOPAJE'!F28 -> 118800 | E7: N/A | F7: N/A | G7: N/A | H7: N/A | I7: N/A | J7: N/A | K7: N/A | L7: N/A | M7: N/A | N7: N/A | O7: N/A | P7: =SUM(D7:O7) -> 118800
B8: 4 | C8: Uniformes | D8: ='4-UNIFORMES'!F34 -> 115200 | E8: N/A | F8: N/A | G8: N/A | H8: N/A | I8: =D8 -> 115200 | J8: N/A | K8: N/A | L8: N/A | M8: N/A | N8: N/A | O8: N/A | P8: =SUM(D8:O8) -> 230400
B9: 5 | C9: Herramientas | D9: ='5-HERRAMIENTAS'!D76:E76 -> 94410 | E9: ='5-HERRAMIENTAS'!$D$77 -> 5530.5 | F9: ='5-HERRAMIENTAS'!$D$77 -> 5530.5 | G9: ='5-HERRAMIENTAS'!$D$77 -> 5530.5 | H9: ='5-HERRAMIENTAS'!$D$77 -> 5530.5 | I9: ='5-HERRAMIENTAS'!D81 -> 9230.5 | J9: ='5-HERRAMIENTAS'!$D$77 -> 5530.5 | K9: ='5-HERRAMIENTAS'!$D$77 -> 5530.5 | L9: ='5-HERRAMIENTAS'!$D$77 -> 5530.5 | M9: ='5-HERRAMIENTAS'!$D$77 -> 5530.5 | N9: ='5-HERRAMIENTAS'!$D$77 -> 5530.5 | O9: ='5-HERRAMIENTAS'!$D$77 -> 5530.5 | P9: =SUM(D9:O9) -> 158945.5
B10: 6 | C10: EPP | D10: ='6-EPP'!D80 -> 24700.67 | E10: ='6-EPP'!D81 -> 2016 | F10: ='6-EPP'!D82 -> 2016 | G10: ='6-EPP'!D83 -> 4331.97 | H10: ='6-EPP'!D84 -> 2016 | I10: ='6-EPP'!D85 -> 8832 | J10: ='6-EPP'!D86 -> 2016 | K10: ='6-EPP'!D87 -> 4331.97 | L10: ='6-EPP'!D88 -> 2016 | M10: ='6-EPP'!D89 -> 2016 | N10: ='6-EPP'!D90 -> 2016 | O10: ='6-EPP'!D91 -> 4331.97 | P10: =SUM(D10:O10) -> 60640.58
B11: 7 | C11: Cuatrimotos | D11: ='7-Cuatrimotos'!F34 -> 22000 | E11: ='7-Cuatrimotos'!$C$40 -> 21990 | F11: ='7-Cuatrimotos'!$C$40 -> 21990 | G11: ='7-Cuatrimotos'!$C$40 -> 21990 | H11: ='7-Cuatrimotos'!$C$40 -> 21990 | I11: ='7-Cuatrimotos'!$C$40 -> 21990 | J11: ='7-Cuatrimotos'!$C$40 -> 21990 | K11: ='7-Cuatrimotos'!$C$40 -> 21990 | L11: ='7-Cuatrimotos'!$C$40 -> 21990 | ... O11: ='7-Cuatrimotos'!$C$40 -> 21990 | P11: =SUM(D11:O11) -> 263890
B12: - | C12: Total | D12: =SUM(D5:D11) -> 1178572.6 | E12: =SUM(E5:E11) -> 832998.45 | F12: =SUM(F5:F11) -> 832998.45 | G12: =SUM(G5:G11) -> 835314.42 | H12: =SUM(H5:H11) -> 832998.45 | I12: =SUM(I5:I11) -> 958714.45 | J12: =SUM(J5:J11) -> 832998.45 | K12: =SUM(K5:K11) -> 835314.42 | ... O12: =SUM(O5:O11) -> 835314.42
C13: Total Global Proyecto
C14: =SUM(D12:O12)+D15 -> 10504220
C15: POLIZA FIDELIDAD | D15: 30000
B19: 8 | C19: Administracion | D19: 0.03
D20: =C14*D19 -> 315126.59
B21: 9 | C21: Utilidad | D21: 0.2
D22: =C14*D21 -> 2100843.9
B23: 10 | C23: Total Global | D23: Total Global con IVA
C24: =C14+D20+D22 -> 12920190 | D24: =C24*1.16 -> 14987420

Sheet 1-Nomina Mes-Año
A7: 1 | B7: Nomina semanal Guardias Planta FCA
B8: Nomina | D8: Real
B9: Cantidad | C9: Puestos | D9: Sueldo | E9: C.P | F9: Total
B10: 1 | C10: Jefe de Seguridad | D10: 6000 | E10: 983.35 | F10: =(D10+E10)*(B10) -> 6983.35
B11: 3 | C11: Sup. FCA | D11: 4800 | E11: 983.35 | F11: =(D11+E11)*(B11) -> 17350.05
B12: 2 | C12: Administrativos | D12: 4000 | E12: 983.35 | F12: =(D12+E12)*(B12) -> 9966.7
B13: 1 | C13: Monitoreo | D13: 4000 | E13: 983.35 | F13: =(D13+E13)*(B13) -> 4983.35
B14: 20 | C14: Oficiales | D14: 3000 | E14: 983.35 | F14: =(D14+E14)*(B14) -> 79667
E15: Total | F15: =SUM(F10:F14) -> 118950.45
B19: Nomina Semanal Mostrada | D19: =F15 -> 118950.45 | E19: Dia | F19: =D19/7 -> 16992.921
B20: Nomina Mensual (Factor 30.5) | D20: =F19*30.5 -> 518284.1
A23: 2 | B23: Nomina semanal Guardias Bodega Estancias Nomina
B24: Nomina | D24: Real
B25: Cantidad | C25: Puestos | D25: Sueldo | E25: C.P | F25: Total
B26: 7 | C26: Oficiales | D26: 3000 | E26: 983.35 | F26: =(D26+E26)*(B26) -> 27883.45
E27: Total | F27: =SUM(F26:F26) -> 27883.45
B29: Nomina Semanal | D29: =F27 -> 27883.45 | E29: Dia | F29: =D29/7 -> 3983.35
B30: Nomina Mensual (Factor 30.5) | D30: =F29*30.5 -> 121492.18
A33: 3 | B33: Nomina semanal Guardias Bodega Norte (NASA)
B34: Nomina | D34: Real
B35: Cantidad | C35: Puestos | D35: Sueldo | E35: C.P | F35: Total
B36: 6 | C36: Oficiales | D36: 3000 | E36: 983.35 | F36: =(D36+E36)*(B36) -> 23900.1
E37: Total | F37: =SUM(F36:F36) -> 23900.1
A39: Adiccional | B39: Nomina Semanal | D39: =F37 -> 23900.1 | E39: Dia | F39: =D39/7 -> 3414.3
B40: Nomina Mensual (Factor 30.5) | D40: =F39*30.5 -> 104136.15
B43: Nomina semanal Guardias Bodega Norte (NASA)
B44: Nomina | D44: Real
B45: Cantidad | C45: Puestos | D45: Sueldo | E45: C.P | F45: Total
B46: 1 | C46: Chofer | D46: 2500 | E46: 983.35 | F46: =(D46+E46)*(B46) -> 3483.35
E47: Total | F47: =SUM(F46:F46) -> 3483.35
C49: REAL
C50: Total Nomina Global Mensual | E50: =D20+D30+D40 -> 743912.43
E51: =E50+F47 -> 747395.78
B64: Nota: El chofer llevara al personal de turno A 15 min antes de la hora de entrada, a la hora entrada del persona turno B el los dejara igual 15 min antes de la hora de entrada regresando a personal de turno A en secuencia.

Sheet 1-Desglozar Nomina
A7: 1 | B7: Nomina semanal Guardias Planta FCA
B8: Nomina | D8: DESGLOSE DE SUELDOS DE PERSONAL
B9: Cantidad | C9: Puestos | D9: Salario Diario | E9: Sueldo Base | F9: BONO | G9: SALARIO NETO | H9: CP | I9: Total
B10: 1 | C10: Jefe de Seguridad | D10: 315.04 | E10: =D10*7 -> 2205.28 | F10: =G10-E10 -> 3794.72 | G10: 6000 | H10: 983.35 | I10: =(E10+F10+H10)*B10 -> 6983.35
B11: 3 | C11: Sup. FCA | D11: 315.04 | E11: =D11*7 -> 2205.28 | F11: =G11-E11 -> 2794.72 | G11: 5000 | H11: 983.35 | I11: =(E11+F11+H11)*B11 -> 17950.05
B12: 2 | C12: Administrativos | D12: 315.04 | E12: =D12*7 -> 2205.28 | F12: =G12-E12 -> 2094.72 | G12: 4300 | H12: 983.35 | I12: =(E12+F12+H12)*B12 -> 10566.7
B13: 1 | C13: Monitoreo | D13: 315.04 | E13: =D13*7 -> 2205.28 | F13: =G13-E13 -> 1794.72 | G13: 4000 | H13: 983.35 | I13: =(E13+F13+H13)*B13 -> 4983.35
B14: 20 | C14: Oficiales | D14: 315.04 | E14: =D14*7 -> 2205.28 | F14: =G14-E14 -> 794.72 | G14: 3000 | H14: 983.35 | I14: =(E14+F14+H14)*B14 -> 79667
H15: Total | I15: =SUM(I10:I14) -> 120150.45
B19: Nomina Semanal Mostrada | D19: =I15 -> 120150.45 | E19: Dia | F19: =D19/7 -> 17164.35
B20: Nomina Mensual (Factor 30.5) | D20: =F19*30.5 -> 523512.68
A23: 2 | B23: Nomina semanal Guardias Bodega Estancias Nomina
B24: Nomina | D24: DESGLOSE DE SUELDOS DE PERSONAL
B25: Cantidad | C25: Puestos | D25: Salario Diario | E25: Sueldo Base | F25: BONO | G25: SALARIO NETO | H25: CP | I25: Total
B26: 7 | C26: Oficiales | D26: 315.04 | E26: =D26*7 -> 2205.28 | F26: =F14 -> 794.72 | G26: =F26+E26 -> 3000 | H26: 983.35 | I26: =(E26+F26+H26)*B26 -> 27883.45
H27: Total | I27: =I26 -> 27883.45
B29: Nomina Semanal | D29: =I27 -> 27883.45 | E29: Dia | F29: =D29/7 -> 3983.35
B30: Nomina Mensual (Factor 30.5) | D30: =F29*30.5 -> 121492.18
A33: 3 | B33: Nomina semanal Guardias Bodega Estancias Nomina
B34: Nomina | D34: DESGLOSE DE SUELDOS DE PERSONAL
B35: Cantidad | C35: Puestos | D35: Salario Diario | E35: Sueldo Base | F35: BONO | G35: SALARIO NETO | H35: CP | I35: Total
B36: 6 | C36: Oficiales | D36: 315.04 | E36: =D36*7 -> 2205.28 | F36: =F26 -> 794.72 | G36: =F36+E36 -> 3000 | H36: 983.35 | I36: =(E36+F36+H36)*B36 -> 23900.1
H37: Total | I37: =I36 -> 23900.1
A39: Adiccional | B39: Nomina Semanal | D39: =I37 -> 23900.1 | E39: Dia | F39: =D39/7 -> 3414.3
B40: Nomina Mensual (Factor 30.5) | D40: =F39*30.5 -> 104136.15
A43: 4 | B43: Nomina semanal Guardias Bodega Norte (NASA)
B44: Nomina | D44: Real
B45: Cantidad | C45: Puestos | D45: Salario Diario | E45: Sueldo Base | F45: BONO | G45: SALARIO NETO | H45: CP | I45: Total
B46: 1 | C46: Chofer | D46: 315.04 | E46: =D46*7 -> 2205.28 | F46: =G46-E46 -> 294.72 | G46: 2500 | H46: 983.35 | I46: =(E46+F46+H46)*B46 -> 3483.35
H47: Total | I47: =I46 -> 3483.35
B49: Nomina Semanal | D49: =I47 -> 3483.35 | E49: Dia | F49: =D49/7 -> 497.62143
B50: Nomina Mensual (Factor 30.5) | D50: =F49*30.5 -> 15177.454
B55: REAL
B56: Total Nomina Global Mensual | D56: =D20+D30+D40+D50 -> 764318.45
D57: =D56+F47 -> 764318.45
B64: Nota: El chofer llevara al personal de turno A 15 min antes de la hora de entrada, a la hora entrada del persona turno B el los dejara igual 15 min antes de la hora de entrada regresando a personal de turno A en secuencia.

Sheet 2-Traslados
B3: 1 | C3: Traslado semanal Guardias Planta FCA
C4: Cantidad | D4: Puestos | E4: TURNO | F4: TRASLADO
C5: 1 | D5: Jefe de Seguridad | E5: A | F5: PROPIO
C6: 1 | D6: Sup. FCA | E6: A | F6: URBAN (1)
C7: 1 | D7: Sup. FCA | E7: B | F7: URBAN (2)
C8: 1 | D8: Sup. Apoyo Monitoreo | E8: B/A | F8: URBAN (2)
C9: 1 | D9: Administrativos | E9: A | F9: URBAN (1)
C10: 1 | D10: Administrativos | E10: B | F10: URBAN (2)
C11: 1 | D11: Monitoreo | E11: A/B | F11: URBAN (1)
C12: 10 | D12: Oficiales | E12: B | F12: URBAN (2)
C13: 10 | D13: Oficiales | E13: A | F13: URBAN (1)
C15: TURNO A | D15: PUESTO | E15: CANTIDAD | G15: TURNO A | H15: PUESTO | I15: CANTIDAD
C16: A | D16: Jefe Coordinador | E16: 0 | G16: A | H16: Jefe Coordinador | I16: 0
C17: A | D17: Sup. FCA | E17: 1 | G17: A | H17: Sup. FCA | I17: 2
C18: A | D18: Administrativos | E18: 1 | G18: A | H18: Administrativos | I18: 1
C19: A | D19: Monitoreo | E19: 1 | G19: A | H19: Monitoreo | I19: 0
C20: A | D20: Oficiales | E20: 10 | G20: A | H20: Oficiales | I20: 10
D21: TOTAL PERSONAL VIAJE | E21: =SUM(E16:E20) -> 13 | H21: TOTAL PERSONAL VIAJE | I21: =SUM(I16:I20) -> 13
C23: PRECIO | D23: DESCRIPCION | E23: SEMANAL | F23: MENSUAL
B24: 1 | C24: URBAN | D24: URBAN RENTADA | E24: - | F24: 23200
B25: 2 | C25: GASOLINA | D25: GASOLINA TRANSPORTE | E25: 3500 | F25: =E25*4 -> 14000
B26: 3 | C26: POLIAZA | D26: Proporcionar /12 | E26: 750 | F26: 1943.5
D27: Total Mensual | E27: =SUM(F24:F26) -> 39143.5 | F27: FCA
B30: 2 | C30: Traslado semanal Guardias Bodega Estancias | H30: C: Cubre Descanso
C31: Cantidad | D31: Puestos | E31: TURNO | F31: TRASLADO | G31: TOTAL
C32: 2 | D32: Oficiales | E32: A | F32: 250 | G32: =F32*C32 -> 500
C33: 3 | D33: Oficiales | E33: B | F33: 250 | G33: =F33*C33 -> 750
C34: 2 | D34: Oficiales | E34: C | F34: 250 | G34: =F34*C34 -> 500
C36: TURNO A | D36: PUESTO | E36: CANTIDAD | G36: TURNO B | H36: PUESTO | I36: CANTIDAD
C37: A | D37: Oficiales | E37: 2 | G37: B | H37: Oficiales | I37: 3
C38: C | D38: Oficiales | E38: 1 | G38: C | H38: Oficiales | I38: 1
C40: PRECIO | D40: DESCRIPCION | E40: SEMANAL | F40: MENSUAL
B41: 7 | C41: 250 | D41: Apoyo Transporte | E41: =C41*B41 -> 1750 | F41: =E41*4 -> 7000
D42: Total Mensual | E42: =SUM(F41:F41) -> 7000 | F42: NORTE
B44: 3 | C44: Traslado semanal Guardias Bodega Tierra Norte (NASA) | H44: C: Cubre Descanso
C45: Cantidad | D45: Puestos | E45: TURNO | F45: TRASLADO
C46: 2 | D46: Oficiales | E46: A | F46: 350
C47: 2 | D47: Oficiales | E47: B | F47: 350
C48: 2 | D48: Oficiales | E48: C | F48: 350
C51: TURNO A | D51: PUESTO | E51: CANTIDAD | G51: TURNO B | H51: PUESTO | I51: CANTIDAD
...

Sheet 3-DC-3 MED-DOPAJE
B4: PERSONAL PLANTA FCA
B5: Cantidad | C5: PRECIO | D5: PERSONAL | E5: CANTIDAD | F5: Total
B6: DC-3 | C6: 300 | D6: 20 | E6: 5 | F6: =C6*D6*E6 -> 30000
B7: MEDI/DOP | C7: 1600 | D7: 20 | E7: 1 | F7: =C7*D7*E7 -> 32000
B8: SELECCIÓN | C8: 500 | D8: 20 | E8: 1 | F8: =C8*D8*E8 -> 10000
E9: Total | F9: =SUM(F6:F8) -> 72000
B12: PERSONAL BODEGA ESTANCIAS
B13: Cantidad | C13: PRECIO | D13: PERSONAL | E13: CANTIDAD | F13: Total
B14: DC-3 | C14: =C6 -> 300 | D14: 7 | E14: 5 | F14: =C14*D14*E14 -> 10500
B15: MEDI/DOP | C15: =C7 -> 1600 | D15: 7 | E15: 1 | F15: =C15*D15*E15 -> 11200
B16: SELECCIÓN | C16: =C8 -> 500 | D16: 7 | E16: 1 | F16: =C16*D16*E16 -> 3500
E17: Total | F17: =SUM(F14:F16) -> 25200
B20: PERSONAL BODEGA NORTE (NASA)
B21: Cantidad | C21: PRECIO | D21: PERSONAL | E21: CANTIDAD | F21: Total
B22: DC-3 | C22: =C14 -> 300 | D22: 6 | E22: 5 | F22: =C22*D22*E22 -> 9000
B23: MEDI/DOP | C23: =C15 -> 1600 | D23: 6 | E23: 1 | F23: =C23*D23*E23 -> 9600
B24: SELECCIÓN | C24: =C16 -> 500 | D24: 6 | E24: 1 | F24: =C24*D24*E24 -> 3000
E25: Total | F25: =SUM(F22:F24) -> 21600
B27: ESTE COBRO ES UNICO, YA QUE ES CERTIFICACION ANUAL
D28: Total Global | F28: =F9+F17+F25 -> 118800 | G28: Unico cobro
B30: RESUMEN DE COBRO
B31: No. Mes | C31: Cantidad
B32: 1 | C32: =F28 -> 118800
B33: 2 | C33: 0
B34: 3 | C34: 0
B35: 4 | C35: 0
B36: 5 | C36: 0
B37: 6 | C37: 0
B38: 7 | C38: 0
B39: 8 | C39: 0
B40: 9 | C40: 0
B41: 10 | C41: 0
B42: 11 | C42: 0
B43: 12 | C43: 0
B45: TOTAL PROYECTO
B46: =SUM(C32:D43) -> 118800

Sheet 4-UNIFORMES
C2: UNIFORMES PERSONAL PROYECTO GUARDIAS DE SEGURIDAD
C3: PERSONAL PLANTA FCA | E3: ITEM PANTALON | H3: ITEM CAMISA | K3: ITEM PLAYERA | N3: ITEM CHAMARRA | Q3: ITEM GORRA | T3: FRECUENCIA
B4: # | C4: PUESTO | E4: PRECIO | F4: CANTIDAD | G4: TOTAL | H4: PRECIO | I4: CANTIDAD | J4: TOTAL | K4: PRECIO | L4: CANTIDAD | M4: TOTAL | N4: PRECIO | O4: CANTIDAD | P4: TOTAL | Q4: PRECIO | R4: CANTIDAD | S4: TOTAL | T4: GLOBAL SEMESTRAL
B5: 1 | C5: JEFE COORDINADOR | E5: 400 | F5: 2 | G5: =E5*F5*B5 -> 800 | H5: 400 | I5: 2 | J5: =H5*I5*B5 -> 800 | K5: 350 | L5: 2 | M5: =K5*L5*B5 -> 700 | N5: 500 | O5: 1 | P5: =N5*O5*B5 -> 500 | Q5: 80 | R5: 1 | S5: =Q5*R5*B5 -> 80 | T5: Total | U5: =G5+J5+M5+P5+S5 -> 2880
B6: 3 | C6: SUP. GUARDIAS | E6: 400 | F6: 2 | G6: =E6*F6*B6 -> 2400 | H6: 400 | I6: 2 | J6: =H6*I6*B6 -> 2400 | K6: 350 | L6: 2 | M6: =K6*L6*B6 -> 2100 | N6: 500 | O6: 1 | P6: =N6*O6*B6 -> 1500 | Q6: 80 | R6: 1 | S6: =Q6*R6*B6 -> 240 | T6: Total | U6: =G6+J6+M6+P6+S6 -> 8640
B7: 2 | C7: ADMINISTRATIVO | E7: 400 | F7: 2 | G7: =E7*F7*B7 -> 1600 | H7: 400 | I7: 2 | J7: =H7*I7*B7 -> 1600 | K7: 350 | L7: 2 | M7: =K7*L7*B7 -> 1400 | N7: 500 | O7: 1 | P7: =N7*O7*B7 -> 1000 | Q7: 80 | R7: 1 | S7: =Q7*R7*B7 -> 160 | T7: Total | U7: =G7+J7+M7+P7+S7 -> 5760
B8: 1 | C8: MONITOREO | E8: 400 | F8: 2 | G8: =E8*F8*B8 -> 800 | H8: 400 | I8: 2 | J8: =H8*I8*B8 -> 800 | K8: 350 | L8: 2 | M8: =K8*L8*B8 -> 700 | N8: 500 | O8: 1 | P8: =N8*O8*B8 -> 500 | Q8: 80 | R8: 1 | S8: =Q8*R8*B8 -> 80 | T8: Total | U8: =G8+J8+M8+P8+S8 -> 2880
B9: 20 | C9: OFICIAL | E9: 400 | F9: 2 | G9: =E9*F9*B9 -> 16000 | H9: 400 | I9: 2 | J9: =H9*I9*B9 -> 16000 | K9: 350 | L9: 2 | M9: =K9*L9*B9 -> 14000 | N9: 500 | O9: 1 | P9: =N9*O9*B9 -> 10000 | Q9: 80 | R9: 1 | S9: =Q9*R9*B9 -> 1600 | T9: Total | U9: =G9+J9+M9+P9+S9 -> 57600
S10: Total Global | U10: =SUM(U5:U9) -> 77760
C11: Este cobro es unicamente al inicio y en el mes numero 6
C12: Inicio de Proyecto | D12: =U10 -> 77760
C13: Cobro Mes 6 | D13: =D12 -> 77760
C15: UNIFORMES PERSONAL PROYECTO GUARDIAS DE SEGURIDAD
C16: PERSONAL BODEGA ESTANCIAS | E16: ITEM PANTALON | H16: ITEM CAMISA | K16: ITEM PLAYERA | N16: ITEM CHAMARRA | Q16: ITEM GORRA | T16: FRECUENCIA
B17: # | C17: PUESTO | E17: PRECIO | F17: CANTIDAD | G17: TOTAL | H17: PRECIO | I17: CANTIDAD | J17: TOTAL | K17: PRECIO | L17: CANTIDAD | M17: TOTAL | N17: PRECIO | O17: CANTIDAD | P17: TOTAL | Q17: PRECIO | R17: CANTIDAD | S17: TOTAL | T17: GLOBAL SEMESTRAL
B18: 7 | C18: OFICIAL | E18: 400 | F18: 2 | G18: =E18*F18*B18 -> 5600 | H18: 400 | I18: 2 | J18: =H18*I18*B18 -> 5600 | K18: 350 | L18: 2 | M18: =K18*L18*B18 -> 4900 | N18: 500 | O18: 1 | P18: =N18*O18*B18 -> 3500 | Q18: 80 | R18: 1 | S18: =Q18*R18*B18 -> 560 | T18: Total | U18: =G18+J18+M18+P18+S18 -> 20160
G19: =G18/400 -> 14 | S19: Total Global | U19: =SUM(U18:U18) -> 20160
C20: Este cobro es unicamente al inicio y en el mes numero 6
C21: Inicio de Proyecto | D21: =U19 -> 20160
C22: Cobro Mes 6 | D22: =D21 -> 20160
C24: UNIFORMES PERSONAL PROYECTO GUARDIAS DE SEGURIDAD
C25: PERSONAL BODEGA NORTE (NASA) | E25: ITEM PANTALON | H25: ITEM CAMISA | K25: ITEM PLAYERA | N25: ITEM CHAMARRA | Q25: ITEM GORRA | T25: FRECUENCIA
B26: # | C26: PUESTO | E26: PRECIO | F26: CANTIDAD | G26: TOTAL | H26: PRECIO | I26: CANTIDAD | J26: TOTAL | K26: PRECIO | L26: CANTIDAD | M26: TOTAL | N26: PRECIO | O26: CANTIDAD | P26: TOTAL | Q26: PRECIO | R26: CANTIDAD | S26: TOTAL | T26: GLOBAL SEMESTRAL
B27: 6 | C27: OFICIAL | E27: 400 | F27: 2 | G27: =E27*F27*B27 -> 4800 | H27: 400 | I27: 2 | J27: =H27*I27*B27 -> 4800 | K27: 350 | L27: 2 | M27: =K27*L27*B27 -> 4200 | N27: 500 | O27: 1 | P27: =N27*O27*B27 -> 3000 | Q27: 80 | R27: 1 | S27: =Q27*R27*B27 -> 480 | T27: Total | U27: =G27+J27+M27+P27+S27 -> 17280
G28: =G27/400 -> 12 | S28: Total Global | U28: =SUM(U27:U27) -> 17280
C29: Este cobro es unicamente al inicio y en el mes numero 6
C30: Inicio de Proyecto | D30: =U28 -> 17280
C31: Cobro Mes 6 | D31: =D30 -> 17280
C34: COBRO GLOBAL INICIO DE PROYECTO | F34: =D12+D21+D30 -> 115200 | G34: 1ER
C35: COBRO GLOBAL 6TO MES DE PROYECTO | F35: =F34 -> 115200 | G35: 6TO
C37: Item | D37: Cantidad
C38: Pantalon | D38: =(F27*B27)+(F18*B18)+(F9*B9)+(B8*F8)+(B7*F7)+(B6*F6)+(B5*F5) -> 80
C39: Camisa | D39: =(I5*B5)+(B6*I6)+(B7*I7)+(B8*I8)+(B9*I9)+(B18*I18)+(B27*I27) -> 80
C40: Playera | D40: =(I6*B6)+(B7*I7)+(B8*I8)+(B9*I9)+(B5*I5)+(B18*I18)+(B27*I27) -> 80
C41: Chamarra | D41: =(O27*B27)+(O18*B18)+(O9*B9)+(B8*O8)+(B7*O7)+(B6*O6)+(B5*O5) -> 40
C42: Gorras | D42: =(R27*B27)+(R18*B18)+(R9*B9)+(B8*R8)+(B7*R7)+(B6*R6)+(B5*R5) -> 40 | E42: 0
C44: RESUMEN DE COBRO
C45: No. Mes | D45: Cantidad
C46: 1 | D46: =F34 -> 115200
C47: 2 | D47: =$N$67+$N$45+$R$23 -> 0
...

Sheet 5-HERRAMIENTAS
C3: Lista de Herramientas pretendidas para personal Seguridad Privda Guardias
E4: 1 | F4: Planta FCA (27) | O4: URREA | P4: Mercado Libre | Q4: Market Place | R4: Amazon | S4: Amazon | U4: Provedoor
C5: Item | E5: Precio | F5: Oficiales (20) | G5: Cantidad | H5: Admin (6) | I5: Cantidad | J5: Jefe (1) | K5: Cantidad | L5: Cantidad Total | M5: Monto Total | N5: Frecuencia | P5: pack 10 $3,800 | R5: Pack 5 $3,000 | S5: pack 10 $7,200 premium | U5: $1100 c/u
B6: 1 | C6: Radio | E6: 1000 | G6: 6 | I6: 2 | K6: 1 | L6: =SUM(F6:K6) -> 9 | M6: =L6*E6 -> 9000 | N6: 10% 2-12 mes
B7: 2 | C7: Lampara | E7: 450 | G7: 8 | I7: - | K7: - | L7: =SUM(F7:K7) -> 8 | M7: =L7*E7 -> 3600 | N7: 10% 2-12 mes | O7: 1300 | P7: 900
B8: 3 | C8: Detector de Metal | E8: 2200 | G8: 2 | I8: - | K8: - | L8: =SUM(F8:K8) -> 2 | M8: =L8*E8 -> 4400 | N8: 10% 2-12 mes | O8: 7300 | P8: 3400 | Q8: 6500
B9: 4 | C9: Alcoholimetro | E9: 2230 | G9: 2 | I9: - | K9: - | L9: =SUM(F9:K9) -> 2 | M9: =L9*E9 -> 4460 | N9: 10% 2-12 mes | O9: ML=$14,299 | P9: KaBla=$11,900 | Q9: $4000- $9000
B10: 5 | C10: Tablet Disp. QR/NFC | E10: 2800 | G10: 4 | I10: - | K10: - | L10: =SUM(F10:K10) -> 4 | M10: =L10*E10 -> 11200 | N10: 10% 2-12 mes | O10: Samsung Galaxy Tab A11
B11: 6 | C11: Sellos | E11: 300 | G11: 1 | I11: - | K11: - | L11: =SUM(F11:K11) -> 1 | M11: =L11*E11 -> 300 | N11: 6 meses
B12: 7 | C12: Biometricos | E12: 1500 | G12: 1 | I12: - | K12: - | L12: =SUM(F12:K12) -> 1 | M12: =L12*E12 -> 1500 | N12: 10% 2-12 mes
B13: 8 | C13: Laptop | E13: 5000 | G13: - | I13: - | K13: 1 | L13: =SUM(F13:K13) -> 1 | M13: =L13*E13 -> 5000 | N13: 10% 2-12 mes
B14: 9 | C14: PC (Escritorio) | E14: 3500 | G14: - | I14: 1 | K14: - | L14: =SUM(F14:K14) -> 1 | M14: =L14*E14 -> 3500 | N14: 10% 2-12 mes
B15: 10 | C15: Impresora | E15: 2000 | G15: - | I15: 1 | K15: - | L15: =SUM(F15:K15) -> 1 | M15: =L15*E15 -> 2000 | N15: 10% 2-12 mes
B16: 11 | C16: Bitacoras | E16: 400 | G16: 2 | I16: - | K16: - | L16: =SUM(F16:K16) -> 2 | M16: =L16*E16 -> 800 | N16: 6 meses
B17: 12 | C17: Plumas Caja C/100 | E17: 200 | G17: 1 | I17: - | K17: - | L17: =SUM(F17:K17) -> 1 | M17: =L17*E17 -> 200 | N17: 6 meses
B18: 13 | C18: Celular Comunicación | E18: 3000 | G18: 2 | I18: 2 | K18: 1 | L18: =SUM(F18:K18) -> 5 | M18: =L18*E18 -> 15000 | N18: 10% 2-12 mes
B19: 14 | C19: Cinturones | E19: 550 | I19: - | L19: 20 | M19: =L19*E19 -> 11000 | N19: 6 meses
B20: 15 | C20: Extintores | E20: 1300 | G20: 1 | L20: =SUM(F20:K20) -> 1 | M20: =L20*E20 -> 1300 | N20: Recargas
B21: 16 | C21: APP QR/NFC | E21: 600 | G21: 1 | L21: =SUM(F21:K21) -> 1 | M21: =L21*E21 -> 600 | N21: Mensual
M22: 1 | N22: Total Global Planta FCA | P22: =SUM(P23:P25) -> 82926
N23: Cobro incial mes 1 | P23: =SUM(M6:M21) -> 73860
N24: Cobro mensual (2-5,7-12) 10% | P24: =(M6+M7+M8+M9+M10+M12+M13+M14+M15+M18)*0.05+M21 -> 3583 | Q24: 10% mensual
N25: Cobro 6to mes | P25: =M17+M16+M11+P24+M21 -> 5483 | Q25: (Mes 6 + 10%)
C26: Lista de Herramientas pretendidas para personal Seguridad Privda Guardias
E27: 2 | F27: Bodega Estancias (7) | K27: URREA | L27: Mercado Libre | M27: Market Place | N27: Amazon | O27: Amazon | Q27: Provedoor
C28: Item | E28: Precio | F28: Oficiales (6) | G28: Cantidad | H28: Cantidad Total | I28: Monto Total | J28: Frecuencia | L28: pack 10 $3,800 | N28: Pack 5 $3,000 | O28: pack 10 $7,200 premium | Q28: $1100 c/u
B29: 1 | C29: Radio | E29: 1000 | G29: 1 | H29: =SUM(F29:G29) -> 1 | I29: =H29*E29 -> 1000 | J29: 10% 2-12 mes
B30: 2 | C30: Lampara | E30: 450 | G30: 1 | H30: =SUM(F30:G30) -> 1 | I30: =H30*E30 -> 450 | J30: 10% 2-12 mes | K30: 1300 | L30: 900
B31: 3 | C31: Detector de Metal | E31: 2200 | G31: - | H31: =SUM(F31:G31) -> 0 | I31: =H31*E31 -> 0 | J31: 10% 2-12 mes | K31: 7300 | L31: 3400 | M31: 6500
B32: 4 | C32: Alcoholimetro | E32: 2230 | G32: - | H32: =SUM(F32:G32) -> 0 | I32: =H32*E32 -> 0 | J32: 10% 2-12 mes | K32: ML=$14,299 | L32: KaBla=$11,900 | M32: $4000- $9000
B33: 5 | C33: Tablet Disp. QR/NFC | E33: 2800 | G33: 1 | H33: =SUM(F33:G33) -> 1 | I33: =H33*E33 -> 2800 | J33: 10% 2-12 mes | K33: Samsung Galaxy Tab A11
B34: 6 | C34: Sellos | E34: 300 | G34: 1 | H34: =SUM(F34:G34) -> 1 | I34: =H34*E34 -> 300 | J34: 6 meses
B35: 7 | C35: Biometricos | E35: 1500 | G35: - | H35: =SUM(F35:G35) -> 0 | I35: =H35*E35 -> 0 | J35: 10% 2-12 mes
B36: 8 | C36: Laptop | E36: 5000 | G36: - | H36: =SUM(F36:G36) -> 0 | I36: =H36*E36 -> 0 | J36: 10% 2-12 mes
B37: 9 | C37: PC (Escritorio) | E37: 3500 | G37: - | H37: =SUM(F37:G37) -> 0 | I37: =H37*E37 -> 0 | J37: 10% 2-12 mes
B38: 10 | C38: Impresora | E38: 2000 | G38: - | H38: =SUM(F38:G38) -> 0 | I38: =H38*E38 -> 0 | J38: 10% 2-12 mes
B39: 11 | C39: Bitacoras | E39: 400 | G39: 1 | H39: =SUM(F39:G39) -> 1 | I39: =H39*E39 -> 400 | J39: 6 meses
B40: 12 | C40: Plumas Caja C/100 | E40: 200 | G40: 1 | H40: =SUM(F40:G40) -> 1 | I40: =H40*E40 -> 200 | J40: 6 meses
B41: 13 | C41: Celular Comunicación | E41: 3000 | G41: 1 | H41: =SUM(F41:G41) -> 1 | I41: =H41*E41 -> 3000 | J41: 10% 2-12 mes
B42: 14 | C42: Cinturones | E42: 550 | H42: =SUM(F42:G42) -> 0 | I42: =H42*E42 -> 0 | J42: 6 meses
...

Sheet 6-EPP
C4: Lista de Uniforme pretendido para personal Seguridad Privda Guardias
E5: 1 | F5: Planta FCA (27)
C6: Item | E6: Precio | F6: Oficiales (20) | G6: Cantidad | H6: Admin (6) | I6: Cantidad | J6: Jefe (1) | K6: Cantidad | L6: Cantidad Total | M6: Monto Total | N6: Frecuencia | O6: 1 | P6: Total Global Planta FCA | R6: =SUM(R7:R12) -> 27814.06
B7: 1 | C7: Cascos | E7: 120.9 | G7: 20 | I7: 6 | K7: 1 | L7: =G7+I7+K7 -> 27 | M7: =L7*E7 -> 3264.3 | N7: Unico | P7: Cobro unico | R7: =SUM(M7:M14) -> 17470.09 | S7: Mes 1
B8: 2 | C8: Tapones | E8: 9 | G8: 20 | I8: 6 | K8: 1 | L8: =(G8+I8+K8)*2 -> 54 | M8: =L8*E8 -> 486 | N8: Mensual | P8: Cobro Mensual | R8: =M8+M9 -> 1360.8 | S8: Mes (2,3,5,7,9-11)
B9: 3 | C9: Lentes | E9: 16.2 | G9: 20 | I9: 6 | K9: 1 | L9: =(G9+I9+K9)*2 -> 54 | M9: =L9*E9 -> 874.8 | N9: Mensual | P9: Cobro 4to mes | R9: =M13+R8 -> 1460.79 | S9: mes 4
B10: 4 | C10: Bota tactica | E10: 240 | G10: 20 | I10: 6 | K10: 1 | L10: =(G10+I10+K10) -> 27 | M10: =L10*E10 -> 6480 | N10: 6 Mes | P10: Cobro 6to mes | R10: =(M10/2)+R8 -> 4600.8 | S10: mes 6
B11: 5 | C11: Gabardinas/Overl | E11: 190 | G11: 5 | I11: 1 | K11: 1 | L11: =G11+I11+K11 -> 7 | M11: =L11*E11 -> 1330 | N11: 6 Mes | P11: Cobro 8vo mes | R11: =R9 -> 1460.79 | S11: mes 8
B12: 6 | C12: Chalecos | E12: 185 | G12: 10 | I12: 4 | K12: 1 | L12: =G12+I12+K12 -> 15 | M12: =L12*E12 -> 2775 | N12: Unico | P12: Cobro 12vo mes | R12: =R11 -> 1460.79 | S12: mes 12
B13: 7 | C13: Silbato (Caja c/100pzs) | E13: 99.99 | G13: 1 | I13: 0 | K13: 0 | L13: =G13+I13+K13 -> 1 | M13: =L13*E13 -> 99.99 | N13: 4 meses
B14: 8 | C14: Gaffete | E14: 80 | G14: 20 | I14: 6 | K14: 1 | L14: =G14+I14+K14 -> 27 | M14: =L14*E14 -> 2160 | N14: 6 Mes
B15: 9 | L15: =G15+I15+K15 -> 0 | M15: =L15*E15 -> 0
B16: 10 | L16: =G16+I16+K16 -> 0 | M16: =L16*E16 -> 0
B17: 11 | L17: =G17+I17+K17 -> 0 | M17: =L17*E17 -> 0
B18: 12 | L18: =G18+I18+K18 -> 0 | M18: =L18*E18 -> 0
B19: 13 | L19: =G19+I19+K19 -> 0 | M19: =L19*E19 -> 0
B20: 14 | L20: =G20+I20+K20 -> 0 | M20: =L20*E20 -> 0
B21: 15 | L21: =G21+I21+K21 -> 0 | M21: =L21*E21 -> 0
C28: Lista de Herramientas pretendidas para personal Seguridad Privda Guardias
E29: 2 | F29: Bodega Estancias (7) | K29: 2 | L29: Total Global Planta FCA | N29: =SUM(N30:N35) -> 6704.46
C30: Item | E30: Precio | F30: Oficiales (7) | G30: Cantidad | H30: Cantidad Total | I30: Monto Total | J30: Frecuencia | L30: Cobro unico | N30: =SUM(I30:I38) -> 3800.49 | O30: Mes 1
B31: 1 | C31: Cascos | E31: 120.9 | G31: 3 | H31: =G31 -> 3 | I31: =H31*E31 -> 362.7 | J31: Unico | L31: Cobro Mensual | N31: =I33+I32 -> 352.8 | O31: Mes (2,3,5,7,9-11)
B32: 2 | C32: Tapones | E32: 9 | G32: 14 | H32: =G32 -> 14 | I32: =H32*E32 -> 126 | J32: Mensual | L32: Cobro 4to mes | N32: =I37+N31 -> 452.79 | O32: mes 4
B33: 3 | C33: Lentes | E33: 16.2 | G33: 14 | H33: =G33 -> 14 | I33: =H33*E33 -> 226.8 | J33: Mensual | L33: Cobro 6to mes | N33: =(I34/2)+N31 -> 1192.8 | O33: mes 6
B34: 4 | C34: Bota tactica | E34: 240 | G34: 7 | H34: =G34 -> 7 | I34: =H34*E34 -> 1680 | J34: 6 Mes | L34: Cobro 8vo mes | N34: =N32 -> 452.79 | O34: mes 8
B35: 5 | C35: Gabardinas/Overl | E35: 190 | G35: 1 | H35: =G35 -> 1 | I35: =H35*E35 -> 190 | J35: 6 Mes | L35: Cobro 12vo mes | N35: =N34 -> 452.79 | O35: mes 12
B36: 6 | C36: Chalecos | E36: 185 | G36: 3 | H36: =G36 -> 3 | I36: =H36*E36 -> 555 | J36: Unico
B37: 7 | C37: Silbato (Caja c/100pzs) | E37: 99.99 | G37: 1 | H37: =G37 -> 1 | I37: =H37*E37 -> 99.99 | J37: 4 meses
B38: 8 | C38: Gaffete | E38: 80 | G38: 7 | H38: =G38 -> 7 | I38: =H38*E38 -> 560 | J38: 6 Mes
B39: 9 | I39: =H39*E39 -> 0
B40: 10 | I40: =H40*E40 -> 0
B41: 11 | I41: =H41*E41 -> 0
B42: 12 | I42: =H42*E42 -> 0
B43: 13 | I43: =H43*E43 -> 0
B44: 14 | I44: =H44*E44 -> 0
B45: 15 | I45: =H45*E45 -> 0
C52: Lista de Herramientas pretendidas para personal Seguridad Privda Guardias
E53: 3 | F53: Bodega NORTE (NASA) (6) | K53: 3 | L53: Total Global Planta FCA | N53: =SUM(N54:N59) -> 5962.06
C54: Item | E54: Precio | F54: Oficiales (6) | G54: Cantidad | H54: Cantidad Total | I54: Monto Total | J54: Frecuencia | L54: Cobro unico | N54: =SUM(I54:I62) -> 3430.09 | O54: Mes 1
B55: 1 | C55: Cascos | E55: 120.9 | G55: 3 | H55: =G55 -> 3 | I55: =H55*E55 -> 362.7 | J55: Unico | L55: Cobro Mensual | N55: =I57+I56 -> 302.4 | O55: Mes (2,3,5,7,9-11)
...

Sheet 7-Cuatrimotos
B3: GUARDIAS FCA
B4: CENTRO DE DISTRIBUIDORA POLARIS SALTILLO
B5: Marca | C5: Modelo | D5: Estado | E5: Precio | F5: Cantidad
E6: 40000 | F6: 2 | G6: =E6*F6 -> 80000
B8: Prorrateado 12 meses | I8: =G6/12 -> 6666.6667
B9: Gasolina estimada por semana | D9: 700 | E9: POR UNIDAD | G9: 4 semanas cotizadas | I9: =D9*F6*4 -> 5600
E10: Ploza de seguros repartida en costo/12 | I10: 2400 | J10: (incluye ambas cuatrimotos)
H11: Total | I11: =SUM(I8:I10) -> 14666.667 | J11: Cobro 1er mes
B19: GUARDIAS NASA
B20: CENTRO DE DISTRIBUIDORA POLARIS SALTILLO
B21: Marca | C21: Modelo | D21: Estado | E21: Precio | F21: Cantidad
D22: Nueva | E22: =E6 -> 40000 | F22: 1 | G22: =E22*F22 -> 40000
B24: Prorrateado 12 meses | I24: =G22/12 -> 3333.3333
B25: Gasolina estimada por semana | D25: 700 | G25: 4 semanas cotizadas | I25: =D25*4*F22 -> 2800
E26: Ploza de seguros repartida en costo/12 | I26: 1200
H27: Total | I27: =SUM(I24:I26) -> 7333.3333 | J27: Cobro 1er mes
H33: ITEM | I33: PRECIO | J33: CANTIDAD | K33: SEMANAS | L33: TOTAL
D34: Total cobro Global Mes 1 | F34: =I11+I27 -> 22000 | H34: Polizas | I34: 1200 | J34: 3 | K34: 1 | L34: =I34*J34*K34 -> 3600
D35: Total Cobro mes 2 a 12 | F35: =I15+I31 -> 0 | H35: Gasolina | I35: 700 | J35: 3 | K35: 4 | L35: =I35*J35*K35 -> 8400
H36: Renta Mes | I36: 3330 | J36: 3 | K36: 1 | L36: =I36*J36*K36 -> 9990
B37: RESUMEN DE COBRO | K37: Total Mes= | L37: =SUM(L34:L36) -> 21990
B38: No. Mes | C38: Cantidad
B39: 1 | C39: =$L$37 -> 21990
B40: 2 | C40: =$L$37 -> 21990
B41: 3 | C41: =$L$37 -> 21990
B42: 4 | C42: =$L$37 -> 21990
B43: 5 | C43: =$L$37 -> 21990
B44: 6 | C44: =$L$37 -> 21990
B45: 7 | C45: =$L$37 -> 21990
B46: 8 | C46: =$L$37 -> 21990
B47: 9 | C47: =$L$37 -> 21990
B48: 10 | C48: =$L$37 -> 21990
B49: 11 | C49: =$L$37 -> 21990
B50: 12 | C50: =$L$37 -> 21990
B52: TOTAL PROYECTO
B53: =SUM(C39:D50) -> 263880
